2021-05-14 15:16:17,745 INFO: Microblog startup [in /home/ruairi/learning_python/Flask_MegaTutorial/app/__init__.py:47]
2021-05-14 15:16:36,523 ERROR: Exception on /edit_profile [POST] [in /home/ruairi/learning_python/Flask_MegaTutorial/venv/lib/python3.8/site-packages/flask/app.py:1891]
Traceback (most recent call last):
  File "/home/ruairi/learning_python/Flask_MegaTutorial/venv/lib/python3.8/site-packages/sqlalchemy/engine/base.py", line 1763, in _execute_context
    self.dialect.do_execute(
  File "/home/ruairi/learning_python/Flask_MegaTutorial/venv/lib/python3.8/site-packages/sqlalchemy/engine/default.py", line 717, in do_execute
    cursor.execute(statement, parameters)
sqlite3.IntegrityError: UNIQUE constraint failed: user.username

The above exception was the direct cause of the following exception:

Traceback (most recent call last):
  File "/home/ruairi/learning_python/Flask_MegaTutorial/venv/lib/python3.8/site-packages/flask/app.py", line 2447, in wsgi_app
    response = self.full_dispatch_request()
  File "/home/ruairi/learning_python/Flask_MegaTutorial/venv/lib/python3.8/site-packages/flask/app.py", line 1952, in full_dispatch_request
    rv = self.handle_user_exception(e)
  File "/home/ruairi/learning_python/Flask_MegaTutorial/venv/lib/python3.8/site-packages/flask/app.py", line 1821, in handle_user_exception
    reraise(exc_type, exc_value, tb)
  File "/home/ruairi/learning_python/Flask_MegaTutorial/venv/lib/python3.8/site-packages/flask/_compat.py", line 39, in reraise
    raise value
  File "/home/ruairi/learning_python/Flask_MegaTutorial/venv/lib/python3.8/site-packages/flask/app.py", line 1950, in full_dispatch_request
    rv = self.dispatch_request()
  File "/home/ruairi/learning_python/Flask_MegaTutorial/venv/lib/python3.8/site-packages/flask/app.py", line 1936, in dispatch_request
    return self.view_functions[rule.endpoint](**req.view_args)
  File "/home/ruairi/learning_python/Flask_MegaTutorial/venv/lib/python3.8/site-packages/flask_login/utils.py", line 272, in decorated_view
    return func(*args, **kwargs)
  File "/home/ruairi/learning_python/Flask_MegaTutorial/app/routes.py", line 88, in edit_profile
    db.session.commit()
  File "<string>", line 2, in commit
  File "/home/ruairi/learning_python/Flask_MegaTutorial/venv/lib/python3.8/site-packages/sqlalchemy/orm/session.py", line 1428, in commit
    self._transaction.commit(_to_root=self.future)
  File "/home/ruairi/learning_python/Flask_MegaTutorial/venv/lib/python3.8/site-packages/sqlalchemy/orm/session.py", line 826, in commit
    self._prepare_impl()
  File "/home/ruairi/learning_python/Flask_MegaTutorial/venv/lib/python3.8/site-packages/sqlalchemy/orm/session.py", line 805, in _prepare_impl
    self.session.flush()
  File "/home/ruairi/learning_python/Flask_MegaTutorial/venv/lib/python3.8/site-packages/sqlalchemy/orm/session.py", line 3260, in flush
    self._flush(objects)
  File "/home/ruairi/learning_python/Flask_MegaTutorial/venv/lib/python3.8/site-packages/sqlalchemy/orm/session.py", line 3400, in _flush
    transaction.rollback(_capture_exception=True)
  File "/home/ruairi/learning_python/Flask_MegaTutorial/venv/lib/python3.8/site-packages/sqlalchemy/util/langhelpers.py", line 70, in __exit__
    compat.raise_(
  File "/home/ruairi/learning_python/Flask_MegaTutorial/venv/lib/python3.8/site-packages/sqlalchemy/util/compat.py", line 211, in raise_
    raise exception
  File "/home/ruairi/learning_python/Flask_MegaTutorial/venv/lib/python3.8/site-packages/sqlalchemy/orm/session.py", line 3360, in _flush
    flush_context.execute()
  File "/home/ruairi/learning_python/Flask_MegaTutorial/venv/lib/python3.8/site-packages/sqlalchemy/orm/unitofwork.py", line 453, in execute
    rec.execute(self)
  File "/home/ruairi/learning_python/Flask_MegaTutorial/venv/lib/python3.8/site-packages/sqlalchemy/orm/unitofwork.py", line 627, in execute
    util.preloaded.orm_persistence.save_obj(
  File "/home/ruairi/learning_python/Flask_MegaTutorial/venv/lib/python3.8/site-packages/sqlalchemy/orm/persistence.py", line 234, in save_obj
    _emit_update_statements(
  File "/home/ruairi/learning_python/Flask_MegaTutorial/venv/lib/python3.8/site-packages/sqlalchemy/orm/persistence.py", line 998, in _emit_update_statements
    c = connection._execute_20(
  File "/home/ruairi/learning_python/Flask_MegaTutorial/venv/lib/python3.8/site-packages/sqlalchemy/engine/base.py", line 1578, in _execute_20
    return meth(self, args_10style, kwargs_10style, execution_options)
  File "/home/ruairi/learning_python/Flask_MegaTutorial/venv/lib/python3.8/site-packages/sqlalchemy/sql/elements.py", line 320, in _execute_on_connection
    return connection._execute_clauseelement(
  File "/home/ruairi/learning_python/Flask_MegaTutorial/venv/lib/python3.8/site-packages/sqlalchemy/engine/base.py", line 1447, in _execute_clauseelement
    ret = self._execute_context(
  File "/home/ruairi/learning_python/Flask_MegaTutorial/venv/lib/python3.8/site-packages/sqlalchemy/engine/base.py", line 1806, in _execute_context
    self._handle_dbapi_exception(
  File "/home/ruairi/learning_python/Flask_MegaTutorial/venv/lib/python3.8/site-packages/sqlalchemy/engine/base.py", line 1987, in _handle_dbapi_exception
    util.raise_(
  File "/home/ruairi/learning_python/Flask_MegaTutorial/venv/lib/python3.8/site-packages/sqlalchemy/util/compat.py", line 211, in raise_
    raise exception
  File "/home/ruairi/learning_python/Flask_MegaTutorial/venv/lib/python3.8/site-packages/sqlalchemy/engine/base.py", line 1763, in _execute_context
    self.dialect.do_execute(
  File "/home/ruairi/learning_python/Flask_MegaTutorial/venv/lib/python3.8/site-packages/sqlalchemy/engine/default.py", line 717, in do_execute
    cursor.execute(statement, parameters)
sqlalchemy.exc.IntegrityError: (sqlite3.IntegrityError) UNIQUE constraint failed: user.username
[SQL: UPDATE user SET username=?, about_me=? WHERE user.id = ?]
[parameters: ('susan', 'I am the author of the Flask Mega-Tutorial ', 2)]
(Background on this error at: http://sqlalche.me/e/14/gkpj)
2021-05-14 15:42:18,669 INFO: Microblog startup [in /home/ruairi/learning_python/Flask_MegaTutorial/app/__init__.py:47]
2021-05-14 15:42:32,137 ERROR: Exception on /edit_profile [POST] [in /home/ruairi/learning_python/Flask_MegaTutorial/venv/lib/python3.8/site-packages/flask/app.py:1891]
Traceback (most recent call last):
  File "/home/ruairi/learning_python/Flask_MegaTutorial/venv/lib/python3.8/site-packages/flask/app.py", line 2447, in wsgi_app
    response = self.full_dispatch_request()
  File "/home/ruairi/learning_python/Flask_MegaTutorial/venv/lib/python3.8/site-packages/flask/app.py", line 1952, in full_dispatch_request
    rv = self.handle_user_exception(e)
  File "/home/ruairi/learning_python/Flask_MegaTutorial/venv/lib/python3.8/site-packages/flask/app.py", line 1821, in handle_user_exception
    reraise(exc_type, exc_value, tb)
  File "/home/ruairi/learning_python/Flask_MegaTutorial/venv/lib/python3.8/site-packages/flask/_compat.py", line 39, in reraise
    raise value
  File "/home/ruairi/learning_python/Flask_MegaTutorial/venv/lib/python3.8/site-packages/flask/app.py", line 1950, in full_dispatch_request
    rv = self.dispatch_request()
  File "/home/ruairi/learning_python/Flask_MegaTutorial/venv/lib/python3.8/site-packages/flask/app.py", line 1936, in dispatch_request
    return self.view_functions[rule.endpoint](**req.view_args)
  File "/home/ruairi/learning_python/Flask_MegaTutorial/venv/lib/python3.8/site-packages/flask_login/utils.py", line 272, in decorated_view
    return func(*args, **kwargs)
  File "/home/ruairi/learning_python/Flask_MegaTutorial/app/routes.py", line 85, in edit_profile
    if form.validate_on_submit():
  File "/home/ruairi/learning_python/Flask_MegaTutorial/venv/lib/python3.8/site-packages/flask_wtf/form.py", line 100, in validate_on_submit
    return self.is_submitted() and self.validate()
  File "/home/ruairi/learning_python/Flask_MegaTutorial/venv/lib/python3.8/site-packages/wtforms/form.py", line 318, in validate
    return super(Form, self).validate(extra)
  File "/home/ruairi/learning_python/Flask_MegaTutorial/venv/lib/python3.8/site-packages/wtforms/form.py", line 150, in validate
    if not field.validate(self, extra):
  File "/home/ruairi/learning_python/Flask_MegaTutorial/venv/lib/python3.8/site-packages/wtforms/fields/core.py", line 226, in validate
    stop_validation = self._run_validation_chain(form, chain)
  File "/home/ruairi/learning_python/Flask_MegaTutorial/venv/lib/python3.8/site-packages/wtforms/fields/core.py", line 246, in _run_validation_chain
    validator(form, self)
  File "/home/ruairi/learning_python/Flask_MegaTutorial/app/forms.py", line 41, in validate_username
    user=User.query.fillter_by(username=self.username.data).first()
AttributeError: 'BaseQuery' object has no attribute 'fillter_by'
