2021-05-14 15:42:36,844 ERROR: Exception on /edit_profile [POST] [in /home/ruairi/learning_python/Flask_MegaTutorial/venv/lib/python3.8/site-packages/flask/app.py:1891]
Traceback (most recent call last):
  File "/home/ruairi/learning_python/Flask_MegaTutorial/venv/lib/python3.8/site-packages/flask/app.py", line 2447, in wsgi_app
    response = self.full_dispatch_request()
  File "/home/ruairi/learning_python/Flask_MegaTutorial/venv/lib/python3.8/site-packages/flask/app.py", line 1952, in full_dispatch_request
    rv = self.handle_user_exception(e)
  File "/home/ruairi/learning_python/Flask_MegaTutorial/venv/lib/python3.8/site-packages/flask/app.py", line 1821, in handle_user_exception
    reraise(exc_type, exc_value, tb)
  File "/home/ruairi/learning_python/Flask_MegaTutorial/venv/lib/python3.8/site-packages/flask/_compat.py", line 39, in reraise
    raise value
  File "/home/ruairi/learning_python/Flask_MegaTutorial/venv/lib/python3.8/site-packages/flask/app.py", line 1950, in full_dispatch_request
    rv = self.dispatch_request()
  File "/home/ruairi/learning_python/Flask_MegaTutorial/venv/lib/python3.8/site-packages/flask/app.py", line 1936, in dispatch_request
    return self.view_functions[rule.endpoint](**req.view_args)
  File "/home/ruairi/learning_python/Flask_MegaTutorial/venv/lib/python3.8/site-packages/flask_login/utils.py", line 272, in decorated_view
    return func(*args, **kwargs)
  File "/home/ruairi/learning_python/Flask_MegaTutorial/app/routes.py", line 85, in edit_profile
    if form.validate_on_submit():
  File "/home/ruairi/learning_python/Flask_MegaTutorial/venv/lib/python3.8/site-packages/flask_wtf/form.py", line 100, in validate_on_submit
    return self.is_submitted() and self.validate()
  File "/home/ruairi/learning_python/Flask_MegaTutorial/venv/lib/python3.8/site-packages/wtforms/form.py", line 318, in validate
    return super(Form, self).validate(extra)
  File "/home/ruairi/learning_python/Flask_MegaTutorial/venv/lib/python3.8/site-packages/wtforms/form.py", line 150, in validate
    if not field.validate(self, extra):
  File "/home/ruairi/learning_python/Flask_MegaTutorial/venv/lib/python3.8/site-packages/wtforms/fields/core.py", line 226, in validate
    stop_validation = self._run_validation_chain(form, chain)
  File "/home/ruairi/learning_python/Flask_MegaTutorial/venv/lib/python3.8/site-packages/wtforms/fields/core.py", line 246, in _run_validation_chain
    validator(form, self)
  File "/home/ruairi/learning_python/Flask_MegaTutorial/app/forms.py", line 41, in validate_username
    user=User.query.fillter_by(username=self.username.data).first()
AttributeError: 'BaseQuery' object has no attribute 'fillter_by'
2021-05-14 15:44:43,336 INFO: Microblog startup [in /home/ruairi/learning_python/Flask_MegaTutorial/app/__init__.py:47]
